Workbook

Sheet B服
A1: 活动编号 | B1: 开始时间 | C1: 结束时间 | D1: 当期人数 | E1: 封挂数 | F1: 活动类型
A2: 75 | B2: 44145 | C2: 44150 | D2: 105551 | E2: 6 | F2: 挑战LIVE（CP）
A3: 97 | B3: 44152 | C3: 44157 | D3: 140490 | E3: 18 | F3: 挑战LIVE（CP）
A4: 76 | B4: 44159 | C4: 44164 | D4: 111269 | E4: 5 | F4: LIVE试炼（EX）
A5: 77 | B5: 44166 | C5: 44171 | D5: 65068 | E5: 8 | F5: 竞演LIVE（对邦）
A6: 78 | B6: 44173 | C6: 44178 | D6: 97199 | E6: 6 | F6: 挑战LIVE（CP）
A7: 79 | B7: 44180 | C7: 44185 | D7: 93184 | E7: 6 | F7: 任务LIVE（协力）
A8: 80 | B8: 44187 | C8: 44192 | D8: 62873 | E8: 0 | F8: 竞演LIVE（对邦）
A9: 81 | B9: 44194 | C9: 44199 | D9: 115205 | E9: 7 | F9: 挑战LIVE（CP）
A10: 82 | B10: 44201 | C10: 44206 | D10: 100265 | E10: 4 | F10: LIVE试炼（EX）
A11: 83 | B11: 44208 | C11: 44213 | D11: 61733 | E11: 4 | F11: 竞演LIVE（对邦）
A12: 84 | B12: 44215 | C12: 44220 | D12: 105022 | E12: 3 | F12: 挑战LIVE（CP）
A13: 85 | B13: 44222 | C13: 44227 | D13: 115091 | E13: 4 | F13: 任务LIVE（协力）
... A29: 102 | B29: 44334 | C29: 44339 | D29: 91995 | E29: 5 | F29: 任务LIVE（协力）
A30: 103 | B30: 44341 | C30: 44346 | D30: 115192 | E30: - | F30: 挑战LIVE（CP）
A31: 104 | B31: 44348 | C31: 44353 | D31: 74300 | E31: - | F31: 竞演LIVE（对邦）
A32: 105 | B32: 44355 | C32: 44360 | D32: 119826 | E32: - | F32: LIVE试炼（EX）
A33: 106 | B33: 44362 | C33: 44367 | D33: 109338 | E33: - | F33: 任务LIVE（协力）
A34: 119 | B34: 44369 | C34: 44374 | D34: 142373 | E34: - | F34: LIVE试炼（EX）
A35: 107 | B35: 44376 | C35: 44381 | D35: 70057 | E35: - | F35: 竞演LIVE（对邦）
A36: 108 | B36: 44383 | C36: 44388 | D36: 113900 | E36: - | F36: 任务LIVE（协力）
A37: 109 | B37: 44390 | C37: 44395 | D37: 131643 | E37: - | F37: LIVE试炼（EX）
A38: 110 | B38: 44397 | C38: 44402 | D38: 67243 | E38: - | F38: 竞演LIVE（对邦）
A39: 111 | B39: 44404 | C39: 44409 | D39: 119968 | E39: - | F39: LIVE试炼（EX）
A40: 112 | B40: 44411 | C40: 44416 | D40: 68826 | E40: - | F40: 竞演LIVE（对邦）
A41: 113 | B41: 44418 | C41: 44423 | D41: 122093 | E41: - | F41: 任务LIVE（协力）
... A154: 228 | B154: 45329 | C154: 45336 | D154: 100936 | E154: - | F154: LIVE试炼（EX）
A155: 229 | B155: 45338 | C155: 45345 | D155: 48909 | E155: 13 | F155: 组曲LIVE（3组曲） | G155: *处理后人数
A156: 230 | B156: 45347 | C156: 45354 | D156: 82223 | E156: - | F156: 竞演LIVE（对邦）
A157: 231 | B157: 45356 | C157: 45363 | D157: 80351 | E157: 1 | F157: 任务LIVE（协力） | G157: *处理后人数
A158: 232 | B158: 45365 | C158: 45372 | D158: 80852 | E158: - | F158: 挑战LIVE（CP）
A159: 233 | B159: 45374 | C159: 45381 | D159: 41934 | E159: - | F159: 组曲LIVE（3组曲）
A160: 234 | B160: 45383 | C160: 45390 | D160: 108929 | E160: - | F160: 挑战LIVE（CP）
A161: 235 | B161: 45392 | C161: 45399 | D161: 173620 | E161: 54 | F161: 任务LIVE（协力） | G161: *处理后人数
A162: 236 | B162: 45401 | C162: 45408 | D162: 131537 | E162: 19 | F162: 竞演LIVE（对邦） | G162: *处理后人数
A163: 237 | B163: 45410 | C163: 45417 | D163: 122337 | E163: - | F163: 团队LIVE FES （5V5）
A164: 238 | B164: 45419 | C164: 45425 | D164: 93660 | E164: 8 | F164: LIVE试炼（EX） | G164: *处理前人数，但不是我的数据
A165: 240 | B165: 45427 | C165: 45434 | D165: 109763 | E165: - | F165: LIVE试炼（EX）
A166: 239 | B166: 45436 | C166: 45443 | D166: 73629 | E166: 20 | F166: 组曲LIVE（3组曲） | G166: *处理前人数
A167: 241 | B167: 45445 | C167: 45452 | D167: 123306 | E167: - | F167: 任务LIVE（协力）
...

Sheet 渠道
A1: 活动编号 | B1: 开始时间 | C1: 结束时间 | D1: 当期人数 | E1: B服同期 | F1: 封挂数 | G1: 活动类型
A2: 113 | B2: 44418 | C2: 44423 | D2: 11715 | E2: =D2/B服!D41 -> 0.095951447 | F2: - | G2: 任务LIVE（协力）
A3: 114 | B3: 44425 | C3: 44430 | D3: 4693 | E3: =D3/B服!D42 -> 0.072095738 | F3: - | G3: 竞演LIVE（对邦）
A4: 115 | B4: 44432 | C4: 44437 | D4: 10141 | E4: =D4/B服!D43 -> 0.098484039 | F4: - | G4: 挑战LIVE（CP）
A5: 116 | B5: 44439 | C5: 44444 | D5: 7511 | E5: =D5/B服!D44 -> 0.084911313 | F5: - | G5: LIVE试炼（EX）
A6: 117 | B6: 44446 | C6: 44451 | D6: 6914 | E6: =D6/B服!D45 -> 0.083096966 | F6: - | G6: 任务LIVE（协力）
A7: 118 | B7: 44453 | C7: 44458 | D7: 3241 | E7: =D7/B服!D46 -> 0.066454788 | F7: - | G7: 竞演LIVE（对邦）
A8: 120 | B8: 44460 | C8: 44465 | D8: 6353 | E8: =D8/B服!D47 -> 0.08949526 | F8: - | G8: 任务LIVE（协力）
A9: 121 | B9: 44467 | C9: 44472 | D9: 3642 | E9: =D9/B服!D48 -> 0.073787431 | F9: - | G9: 竞演LIVE（对邦）
A10: 122 | B10: 44474 | C10: 44479 | D10: 6943 | E10: =D10/B服!D49 -> 0.089713274 | F10: - | G10: 任务LIVE（协力）
A11: 123 | B11: 44481 | C11: 44486 | D11: 6757 | E11: =D11/B服!D50 -> 0.09587525 | F11: - | G11: LIVE试炼（EX）
A12: 124 | B12: 44488 | C12: 44493 | D12: 3010 | E12: =D12/B服!D51 -> 0.067670863 | F12: - | G12: 竞演LIVE（对邦）
A13: 125 | B13: 44495 | C13: 44500 | D13: 7170 | E13: =D13/B服!D52 -> 0.10105423 | F13: - | G13: 任务LIVE（协力）
... A99: 211 | B99: 45185 | C99: 45192 | D99: 10545 | E99: =D99/B服!D138 -> 0.14186353 | F99: - | G99: 任务LIVE（协力）
A100: 212 | B100: 45194 | C100: 45201 | D100: 坏了忘截图了 | F100: - | G100: 竞演LIVE（对邦）
A101: 213 | B101: 45203 | C101: 45210 | D101: 11217 | E101: =D101/B服!D140 -> 0.13509412 | F101: - | G101: LIVE试炼（EX）
A102: 214 | B102: 45212 | C102: 45219 | D102: 4882 | E102: =D102/B服!D141 -> 0.10427613 | F102: - | G102: 组曲LIVE（3组曲）
A103: 215 | B103: 45221 | C103: 45228 | D103: 5648 | E103: =D103/B服!D142 -> 0.10248594 | F103: - | G103: 竞演LIVE（对邦）
A104: 216 | B104: 45229 | C104: 45236 | D104: 11120 | E104: =D104/B服!D143 -> 0.13445703 | F104: - | G104: 任务LIVE（协力）
A105: 217 | B105: 45238 | C105: 45245 | D105: 13756 | E105: =D105/B服!D144 -> 0.10331826 | F105: - | G105: 挑战LIVE（CP）
A106: 218 | B106: 45247 | C106: 45254 | D106: 14856 | E106: =D106/B服!D145 -> 0.11884325 | F106: - | G106: LIVE试炼（EX）
A107: 219 | B107: 45256 | C107: 45263 | D107: 14890 | E107: =D107/B服!D146 -> 0.13177924 | F107: - | G107: 任务LIVE（协力）
A108: 220 | B108: 45265 | C108: 45272 | D108: 5002 | E108: =D108/B服!D147 -> 0.09756383 | F108: - | G108: 组曲LIVE（3组曲）
A109: 221 | B109: 45274 | C109: 45281 | D109: 13444 | E109: =D109/B服!D148 -> 0.13820328 | F109: - | G109: 挑战LIVE（CP）
A110: 222 | B110: 45283 | C110: 45290 | D110: 13988 | E110: =D110/B服!D149 -> 0.15308177 | F110: - | G110: LIVE试炼（EX）
A111: 223 | B111: 45292 | C111: 45299 | D111: 12465 | E111: =D111/B服!D150 -> 0.15063808 | F111: - | G111: 任务LIVE（协力）
A112: 224 | B112: 45301 | C112: 45308 | D112: 5031 | E112: =D112/B服!D151 -> 0.10397206 | F112: - | G112: 竞演LIVE（对邦）
... A124: 237 | B124: 45410 | C124: 45417 | D124: 19619 | E124: =D124/B服!D163 -> 0.16036849 | F124: - | G124: 团队LIVE FES （5V5）
A125: 238 | B125: 45419 | C125: 45425 | D125: 没探 | F125: - | G125: LIVE试炼（EX）
A126: 240 | B126: 45427 | C126: 45434 | D126: 13657 | E126: =D126/B服!D165 -> 0.12442262 | F126: - | G126: LIVE试炼（EX）
A127: 239 | B127: 45436 | C127: 45443 | D127: 5676 | E127: =D127/B服!D166 -> 0.07708919 | F127: - | G127: 组曲LIVE（3组曲）
A128: 241 | B128: 45445 | C128: 45452 | D128: 17831 | E128: =D128/B服!D167 -> 0.14460772 | F128: - | G128: 任务LIVE（协力）
A129: 242 | B129: 45454 | C129: 45461 | D129: 15815 | E129: =D129/B服!D168 -> 0.13658465 | F129: - | G129: 挑战LIVE（CP）
A130: 243 | B130: 45463 | C130: 45470 | D130: 17576 | E130: =D130/B服!D169 -> 0.15633394 | F130: - | G130: 团队LIVE FES （5V5）
A131: 244 | B131: 45472 | C131: 45479 | D131: 6207 | E131: =D131/B服!D170 -> 0.1143115 | F131: - | G131: 组曲LIVE（3组曲）
A132: 245 | B132: 45481 | C132: 45488 | D132: 21463 | E132: =D132/B服!D171 -> 0.18363907 | F132: - | G132: 挑战LIVE（CP）
A133: 246 | B133: 45490 | C133: 45497 | D133: 20662+ | E133: 18.01%+ | F133: - | G133: LIVE试炼（EX）
A134: 227 | B134: 45499 | C134: 45506 | D134: 25016 | E134: =D134/B服!D173 -> 0.15732047 | F134: - | G134: 任务LIVE（协力）
A135: 247 | B135: 45509 | C135: 45516 | D135: 21016 | E135: =D135/B服!D174 -> 0.19132588 | F135: - | G135: 竞演LIVE（对邦）
A136: 248 | B136: 45518 | C136: 45525 | D136: 23349 | E136: =D136/B服!D175 -> 0.20758726 | F136: - | G136: 任务LIVE（协力）
...
